<robot name="onshape">
<link name="car_link">
<visual>
<origin xyz="0.070000000000000034417 -0.089000000000000092926 1.2845280394913071349e-16" rpy="4.9303806576313226891e-32 1.4432899320127035026e-15 1.5707963267948947816" />
<geometry>
<mesh filename="package:///car_link.stl"/>
</geometry>
<material name="car_link_material">
<color rgba="0.79215686274509800047 0.81960784313725487671 0.93333333333333334814 1.0"/>
</material>
</visual>
<collision>
<origin xyz="0.070000000000000034417 -0.089000000000000092926 1.2845280394913071349e-16" rpy="4.9303806576313226891e-32 1.4432899320127035026e-15 1.5707963267948947816" />
<geometry>
<mesh filename="package:///car_link.stl"/>
</geometry>
</collision>
<inertial>
<origin xyz="-8.0792827294974415e-08 -0.00029399224686504910053 0.041690808771539626665" rpy="0 0 0"/>
<mass value="1.4917848461152376505" />
<inertia ixx="0.0054742713586083220287" ixy="1.5570169247996331444e-10"  ixz="1.0980481213835968122e-08" iyy="0.0040696032117884329074" iyz="-3.2559022251880480405e-06" izz="0.0056507774047397192271" />
</inertial>
</link>

<link name="assembly_1">
<visual>
<origin xyz="0 0.030999981675389996771 -0.0056518448773737461899" rpy="2.1692574143828551494e-17 -1.570796326794896558 0" />
<geometry>
<mesh filename="package:///pr16_a01_tire_2.stl"/>
</geometry>
<material name="pr16_a01_tire_2_material">
<color rgba="0.26274509803921569651 0.28235294117647058432 0.30196078431372547213 1.0"/>
</material>
</visual>
<collision>
<origin xyz="0 0.030999981675389996771 -0.0056518448773737461899" rpy="2.1692574143828551494e-17 -1.570796326794896558 0" />
<geometry>
<mesh filename="package:///pr16_a01_tire_2.stl"/>
</geometry>
</collision>
<visual>
<origin xyz="0 0 -0.0062000000000100169428" rpy="3.141592653589793116 1.6264382251535596775e-32 2.1692574143828551494e-17" />
<geometry>
<mesh filename="package:///p30_isp_a001_3d.stl"/>
</geometry>
<material name="p30_isp_a001_3d_material">
<color rgba="0.26274509803921569651 0.28235294117647058432 0.30196078431372547213 1.0"/>
</material>
</visual>
<collision>
<origin xyz="0 0 -0.0062000000000100169428" rpy="3.141592653589793116 1.6264382251535596775e-32 2.1692574143828551494e-17" />
<geometry>
<mesh filename="package:///p30_isp_a001_3d.stl"/>
</geometry>
</collision>
<inertial>
<origin xyz="-1.5487334166844589248e-06 -8.5814345018492923711e-08 -0.0050301561806493219273" rpy="0 0 0"/>
<mass value="0.03207771713809098868" />
<inertia ixx="1.2358596404452204434e-05" ixy="4.3615492917198882394e-10"  ixz="-1.667694698618963425e-11" iyy="1.2345010752383234556e-05" iyz="-5.7827554652492551165e-09" izz="2.2976553031712314832e-05" />
</inertial>
</link>

<joint name="LeftWheel" type="revolute">
<origin xyz="0.078500000000000166867 -0.034000000000000030198 0.02500000000000004996" rpy="-1.570796326794896558 1.4312143091539777373 1.5707963267948978903" />
<parent link="car_link" />
<child link="assembly_1" />
<axis xyz="0 0 1"/>
<limit effort="1" velocity="20" />
<joint_properties friction="0.0"/>
</joint>

<link name="assembly_1_2">
<visual>
<origin xyz="-8.6736173798840354721e-19 0 -0.006200000000010003065" rpy="3.141592653589793116 -2.2125674404552151571e-32 6.9186391990699090735e-17" />
<geometry>
<mesh filename="package:///p30_isp_a001_3d.stl"/>
</geometry>
<material name="p30_isp_a001_3d_material">
<color rgba="0.26274509803921569651 0.28235294117647058432 0.30196078431372547213 1.0"/>
</material>
</visual>
<collision>
<origin xyz="-8.6736173798840354721e-19 0 -0.006200000000010003065" rpy="3.141592653589793116 -2.2125674404552151571e-32 6.9186391990699090735e-17" />
<geometry>
<mesh filename="package:///p30_isp_a001_3d.stl"/>
</geometry>
</collision>
<visual>
<origin xyz="8.6736173798840354721e-19 0.03099998167539000718 -0.0056518448773737461899" rpy="6.9186391990699090735e-17 -1.570796326794896558 0" />
<geometry>
<mesh filename="package:///pr16_a01_tire_2.stl"/>
</geometry>
<material name="pr16_a01_tire_2_material">
<color rgba="0.26274509803921569651 0.28235294117647058432 0.30196078431372547213 1.0"/>
</material>
</visual>
<collision>
<origin xyz="8.6736173798840354721e-19 0.03099998167539000718 -0.0056518448773737461899" rpy="6.9186391990699090735e-17 -1.570796326794896558 0" />
<geometry>
<mesh filename="package:///pr16_a01_tire_2.stl"/>
</geometry>
</collision>
<inertial>
<origin xyz="-1.5487334166835617052e-06 -8.5814345013680731015e-08 -0.0050301561806493149884" rpy="0 0 0"/>
<mass value="0.03207771713809098868" />
<inertia ixx="1.2358596404452204434e-05" ixy="4.361549291717472355e-10"  ixz="-1.6676946986154420913e-11" iyy="1.2345010752383234556e-05" iyz="-5.7827554652491599907e-09" izz="2.2976553031712314832e-05" />
</inertial>
</link>

<joint name="RightWheel" type="revolute">
<origin xyz="-0.078500000000000291767 -0.034000000000000044076 0.02500000000000004996" rpy="-1.570796326794896558 1.0543435529566484998 -1.57079632679489678" />
<parent link="car_link" />
<child link="assembly_1_2" />
<axis xyz="0 0 1"/>
<limit effort="1" velocity="20" />
<joint_properties friction="0.0"/>
</joint>

<link name="right_claw">
<visual>
<origin xyz="0.0074999999999999988551 -0.17749999999999999112 0.023500000000000000056" rpy="3.141592653589793116 -5.4838385157121393167e-32 1.0514097037387974864e-18" />
<geometry>
<mesh filename="package:///right_claw.stl"/>
</geometry>
<material name="right_claw_material">
<color rgba="0.50196078431372548323 0.50196078431372548323 0.50196078431372548323 1.0"/>
</material>
</visual>
<collision>
<origin xyz="0.0074999999999999988551 -0.17749999999999999112 0.023500000000000000056" rpy="3.141592653589793116 -5.4838385157121393167e-32 1.0514097037387974864e-18" />
<geometry>
<mesh filename="package:///right_claw.stl"/>
</geometry>
</collision>
<inertial>
<origin xyz="0.13161031125667496666 -0.15634229581481434712 0.0087073712694376460136" rpy="0 0 0"/>
<mass value="0.077433187135449055294" />
<inertia ixx="0.0010380342021609899501" ixy="0.00015302945284854561035"  ixz="1.8999232012475426259e-06" iyy="0.00018632777059713365002" iyz="-2.5063978661754547605e-06" izz="0.0012127555084622649532" />
</inertial>
</link>

<joint name="RightClaw" type="revolute">
<origin xyz="-0.0050000000000001952605 -0.10400000000000012013 0.047500000000000167089" rpy="-3.1415926535897926719 -5.9913170964877163588e-16 3.128025583921072883" />
<parent link="car_link" />
<child link="right_claw" />
<axis xyz="0 0 1"/>
<limit effort="1" velocity="20" />
<joint_properties friction="0.0"/>
</joint>

<link name="left_claw">
<visual>
<origin xyz="0.032499999999999994171 -0.17749999999999999112 0.023500000000000000056" rpy="-3.141592653589793116 1.0720342654554461735e-32 9.3875871167830618372e-18" />
<geometry>
<mesh filename="package:///left_claw.stl"/>
</geometry>
<material name="left_claw_material">
<color rgba="0.50196078431372548323 0.50196078431372548323 0.50196078431372548323 1.0"/>
</material>
</visual>
<collision>
<origin xyz="0.032499999999999994171 -0.17749999999999999112 0.023500000000000000056" rpy="-3.141592653589793116 1.0720342654554461735e-32 9.3875871167830618372e-18" />
<geometry>
<mesh filename="package:///left_claw.stl"/>
</geometry>
</collision>
<inertial>
<origin xyz="-0.13161031125667541075 -0.15634229581481351445 0.0087073712694376321358" rpy="0 0 0"/>
<mass value="0.077433187135448430793" />
<inertia ixx="0.0010380342021609784576" ixy="-0.00015302945284854956769"  ixz="-1.8999232012475358497e-06" iyy="0.00018632777059713099372" iyz="-2.5063978661752133561e-06" izz="0.0012127555084622506417" />
</inertial>
</link>

<joint name="LeftClaw" type="revolute">
<origin xyz="0.0049999999999998240297 -0.10400000000000014788 0.050000000000000169309" rpy="3.141592653589793116 -3.9580907866572562926e-16 3.0015673980571331292" />
<parent link="car_link" />
<child link="left_claw" />
<axis xyz="0 0 1"/>
<limit effort="1" velocity="20" />
<joint_properties friction="0.0"/>
</joint>


</robot>
